[2020-12-16 20:59:38,671 INFO root] Taurus CLI Tool v1.15.0
[2020-12-16 20:59:38,671 DEBUG root] Command-line options: {'log': '/tmp/bzt_oxzew2v7.log', 'option': ['modules.console.disable=true'], 'quiet': None, 'verbose': None, 'no_system_configs': None, 'aliases': []}
[2020-12-16 20:59:38,671 DEBUG root] Python: CPython 3.8.0
[2020-12-16 20:59:38,671 DEBUG root] OS: uname_result(system='Linux', node='2c5d12f185f0', release='5.4.0-1029-aws', version='#30~18.04.1-Ubuntu SMP Tue Oct 20 11:09:25 UTC 2020', machine='x86_64', processor='x86_64')
[2020-12-16 20:59:38,672 INFO root] Starting with configs: ['bitbucket.yml']
[2020-12-16 20:59:38,672 DEBUG root] Using personal config: /root/.bzt-rc
[2020-12-16 20:59:38,672 INFO Engine] Configuring...
[2020-12-16 20:59:38,672 DEBUG Engine] Reading system configs from: /etc/bzt.d
[2020-12-16 20:59:38,682 DEBUG Engine] Base configs list: ['/usr/local/lib/python3.8/dist-packages/bzt/resources/10-base-config.yml', '/etc/bzt.d/50-pbench-enhanced.json', '/etc/bzt.d/90-artifacts-dir.json', '/etc/bzt.d/99-zinstallID.json']
[2020-12-16 20:59:38,682 DEBUG Engine.Configuration] Configs: ['/usr/local/lib/python3.8/dist-packages/bzt/resources/10-base-config.yml', '/etc/bzt.d/50-pbench-enhanced.json', '/etc/bzt.d/90-artifacts-dir.json', '/etc/bzt.d/99-zinstallID.json']
[2020-12-16 20:59:38,682 DEBUG Engine.Configuration] Reading /usr/local/lib/python3.8/dist-packages/bzt/resources/10-base-config.yml as YAML
[2020-12-16 20:59:38,697 DEBUG Engine.Configuration] Reading /etc/bzt.d/50-pbench-enhanced.json as YAML
[2020-12-16 20:59:38,698 DEBUG Engine.Configuration] Reading /etc/bzt.d/90-artifacts-dir.json as YAML
[2020-12-16 20:59:38,698 DEBUG Engine.Configuration] Reading /etc/bzt.d/99-zinstallID.json as YAML
[2020-12-16 20:59:38,698 DEBUG Engine] User configs list: ['/root/.bzt-rc', 'bitbucket.yml']
[2020-12-16 20:59:38,698 DEBUG Engine.Configuration] Configs: ['/root/.bzt-rc', 'bitbucket.yml']
[2020-12-16 20:59:38,699 DEBUG Engine.Configuration] Reading /root/.bzt-rc as YAML
[2020-12-16 20:59:38,701 DEBUG Engine.Configuration] Reading bitbucket.yml as YAML
[2020-12-16 20:59:38,709 DEBUG Engine.Configuration] Configs: ['/root/.bzt-rc', 'bitbucket.yml']
[2020-12-16 20:59:38,709 DEBUG Engine.Configuration] Reading /root/.bzt-rc as YAML
[2020-12-16 20:59:38,711 DEBUG Engine.Configuration] Reading bitbucket.yml as YAML
[2020-12-16 20:59:38,724 DEBUG Engine] Requesting updates info: https://gettaurus.org/updates/?version=1.15.0&installID=Docker
[2020-12-16 20:59:38,724 DEBUG ConfigOverrider] Applying modules.console.disable=true
[2020-12-16 20:59:38,724 DEBUG HTTPClient] Making HTTP request GET https://gettaurus.org/updates/?version=1.15.0&installID=Docker
[2020-12-16 20:59:38,724 DEBUG ConfigOverrider] Applying: [disable]=true
[2020-12-16 20:59:38,725 DEBUG ConfigOverrider] Parsed override value: 'true' -> True (<class 'bool'>)
[2020-12-16 20:59:38,725 INFO Engine] Artifacts dir: /dc-app-performance-toolkit/app/results/bitbucket/2020-12-16_20-59-38
[2020-12-16 20:59:38,726 DEBUG Engine] New artifact filename: /dc-app-performance-toolkit/app/results/bitbucket/2020-12-16_20-59-38/effective
[2020-12-16 20:59:38,727 DEBUG urllib3.connectionpool] Starting new HTTPS connection (1): gettaurus.org:443
[2020-12-16 20:59:38,727 DEBUG Engine.Configuration] Dumping YAML config into /dc-app-performance-toolkit/app/results/bitbucket/2020-12-16_20-59-38/effective.yml
[2020-12-16 20:59:38,741 DEBUG Engine.Configuration] Dumping JSON config into /dc-app-performance-toolkit/app/results/bitbucket/2020-12-16_20-59-38/effective.json
[2020-12-16 20:59:38,741 DEBUG Engine] New artifact filename: /dc-app-performance-toolkit/app/results/bitbucket/2020-12-16_20-59-38/merged.yml
[2020-12-16 20:59:38,742 DEBUG Engine.Configuration] Dumping YAML config into /dc-app-performance-toolkit/app/results/bitbucket/2020-12-16_20-59-38/merged.yml
[2020-12-16 20:59:38,746 DEBUG Engine] New artifact filename: /dc-app-performance-toolkit/app/results/bitbucket/2020-12-16_20-59-38/merged.json
[2020-12-16 20:59:38,746 DEBUG Engine.Configuration] Dumping JSON config into /dc-app-performance-toolkit/app/results/bitbucket/2020-12-16_20-59-38/merged.json
[2020-12-16 20:59:38,746 DEBUG Engine] Add existing artifact (move=False): bitbucket.yml
[2020-12-16 20:59:38,746 DEBUG Engine] Copying bitbucket.yml to /dc-app-performance-toolkit/app/results/bitbucket/2020-12-16_20-59-38/bitbucket.yml
[2020-12-16 20:59:38,747 DEBUG Engine] Set PYTHONPATH to '/root/.bzt/python-packages/3.8.0' + '/dc-app-performance-toolkit/app/results/bitbucket/2020-12-16_20-59-38/python-packages/3.8.0' + 
[2020-12-16 20:59:38,747 DEBUG Engine] Content of user packages dir: %s
[2020-12-16 20:59:38,747 DEBUG Engine] OS env: OBJC_DISABLE_INITIALIZE_FORK_SAFETY=YES
[2020-12-16 20:59:38,747 DEBUG Engine] OS env: application_hostname=bitbucket-loadbala-cs8s8ccqbfud-30797893.us-west-1.elb.amazonaws.com
[2020-12-16 20:59:38,747 DEBUG Engine] OS env: application_protocol=http
[2020-12-16 20:59:38,747 DEBUG Engine] OS env: application_port=80
[2020-12-16 20:59:38,747 DEBUG Engine] OS env: secure=True
[2020-12-16 20:59:38,747 DEBUG Engine] OS env: admin_login=admin
[2020-12-16 20:59:38,747 DEBUG Engine] OS env: admin_password=admin
[2020-12-16 20:59:38,747 DEBUG Engine] OS env: load_executor=jmeter
[2020-12-16 20:59:38,747 DEBUG Engine] OS env: concurrency=20
[2020-12-16 20:59:38,747 DEBUG Engine] OS env: test_duration=50m
[2020-12-16 20:59:38,747 DEBUG Engine] OS env: ramp-up=10m
[2020-12-16 20:59:38,748 DEBUG Engine] OS env: total_actions_per_hour=32700
[2020-12-16 20:59:38,748 DEBUG Engine] OS env: WEBDRIVER_VISIBLE=False
[2020-12-16 20:59:38,748 DEBUG Engine] OS env: JMETER_VERSION=5.2.1
[2020-12-16 20:59:38,748 DEBUG Engine] OS env: LANGUAGE=en_US.utf8
[2020-12-16 20:59:38,748 DEBUG Engine] OS env: allow_analytics=True
[2020-12-16 20:59:38,748 DEBUG Engine] OS env: TAURUS_ARTIFACTS_DIR=/dc-app-performance-toolkit/app/results/bitbucket/2020-12-16_20-59-38
[2020-12-16 20:59:38,748 DEBUG root] Closing log handler: /tmp/bzt_oxzew2v7.log
[2020-12-16 20:59:38,748 DEBUG root] Switched writing logs to /dc-app-performance-toolkit/app/results/bitbucket/2020-12-16_20-59-38/bzt.log
[2020-12-16 20:59:38,748 DEBUG root] Linting config
[2020-12-16 20:59:38,750 INFO Engine] Preparing...
[2020-12-16 20:59:38,751 DEBUG Engine] Module config: consolidator {'class': 'bzt.modules.aggregator.ConsolidatingAggregator', 'rtimes-len': 0, 'percentiles': []}
[2020-12-16 20:59:38,751 DEBUG root] Importing module: bzt.modules.aggregator
[2020-12-16 20:59:38,849 DEBUG root] Loading class: 'ConsolidatingAggregator' from <module 'bzt.modules.aggregator' from '/usr/local/lib/python3.8/dist-packages/bzt/modules/aggregator.py'>
[2020-12-16 20:59:38,849 DEBUG Engine.consolidator] Buffer scaling setup: percentile None from [] selected
[2020-12-16 20:59:38,849 DEBUG Engine] Module config: monitoring {'class': 'bzt.modules.monitoring.Monitoring'}
[2020-12-16 20:59:38,850 DEBUG root] Importing module: bzt.modules.monitoring
[2020-12-16 20:59:38,851 DEBUG root] Loading class: 'Monitoring' from <module 'bzt.modules.monitoring' from '/usr/local/lib/python3.8/dist-packages/bzt/modules/monitoring.py'>
[2020-12-16 20:59:38,851 DEBUG Engine] Module config: shellexec {'class': 'bzt.modules.shellexec.ShellExecutor'}
[2020-12-16 20:59:38,851 DEBUG root] Importing module: bzt.modules.shellexec
[2020-12-16 20:59:38,855 DEBUG easyprocess] version=0.3
[2020-12-16 20:59:38,856 DEBUG pyvirtualdisplay] version=1.3.2
[2020-12-16 20:59:38,862 DEBUG root] Loading class: 'ShellExecutor' from <module 'bzt.modules.shellexec' from '/usr/local/lib/python3.8/dist-packages/bzt/modules/shellexec.py'>
[2020-12-16 20:59:38,863 DEBUG Engine.shellexec] Added prepare task: {'command': 'python util/pre_run/environment_checker.py'}
[2020-12-16 20:59:38,863 DEBUG Engine.shellexec] Added prepare task: {'command': 'python util/pre_run/git_client_check.py'}
[2020-12-16 20:59:38,863 DEBUG Engine.shellexec] Added prepare task: {'command': 'python util/data_preparation/bitbucket_prepare_data.py'}
[2020-12-16 20:59:38,863 DEBUG Engine.shellexec] Added shutdown task: {'command': 'python util/post_run/jmeter_post_check.py'}
[2020-12-16 20:59:38,863 DEBUG Engine.shellexec] Added shutdown task: {'command': 'python util/jtl_convertor/jtls-to-csv.py kpi.jtl selenium.jtl'}
[2020-12-16 20:59:38,863 DEBUG Engine.shellexec] Added post-process task: {'command': 'python util/analytics/analytics.py bitbucket'}
[2020-12-16 20:59:38,863 DEBUG Engine.shellexec] Added post-process task: {'command': 'python util/post_run/cleanup_results_dir.py'}
[2020-12-16 20:59:38,863 INFO Engine.shellexec.Task] Starting shell command: python util/pre_run/environment_checker.py
[2020-12-16 20:59:38,863 DEBUG root] Executing shell: python util/pre_run/environment_checker.py at /dc-app-performance-toolkit/app
[2020-12-16 20:59:38,954 DEBUG Engine.shellexec.Task] Output for python util/pre_run/environment_checker.py:
Python version: (3, 8, 0)
Data Center App Performance Toolkit version: 3.2.0

[2020-12-16 20:59:38,954 DEBUG Engine.shellexec.Task] Task was finished with exit code 0: python util/pre_run/environment_checker.py
[2020-12-16 20:59:38,954 INFO Engine.shellexec.Task] Starting shell command: python util/pre_run/git_client_check.py
[2020-12-16 20:59:38,954 DEBUG root] Executing shell: python util/pre_run/git_client_check.py at /dc-app-performance-toolkit/app
[2020-12-16 20:59:38,981 DEBUG Engine.shellexec.Task] Output for python util/pre_run/git_client_check.py:
Git version: b'git version 2.17.1\n'

[2020-12-16 20:59:38,981 DEBUG Engine.shellexec.Task] Task was finished with exit code 0: python util/pre_run/git_client_check.py
[2020-12-16 20:59:38,981 INFO Engine.shellexec.Task] Starting shell command: python util/data_preparation/bitbucket_prepare_data.py
[2020-12-16 20:59:38,981 DEBUG root] Executing shell: python util/data_preparation/bitbucket_prepare_data.py at /dc-app-performance-toolkit/app
[2020-12-16 20:59:39,387 DEBUG urllib3.connectionpool] https://gettaurus.org:443 "GET /updates/?version=1.15.0&installID=Docker HTTP/1.1" 200 39
[2020-12-16 20:59:39,388 DEBUG Engine] Taurus updates info: {'latest': '1.15.1', 'needsUpgrade': True}
[2020-12-16 20:59:39,388 WARNING Engine] There is newer version of Taurus 1.15.1 available, consider upgrading. What's new: http://gettaurus.org/docs/Changelog/
[2020-12-16 21:00:12,208 DEBUG Engine.shellexec.Task] Output for python util/data_preparation/bitbucket_prepare_data.py:
Started preparing data
Server url:  http://bitbucket-loadbala-cs8s8ccqbfud-30797893.us-west-1.elb.amazonaws.com:80
Attempt to fetch [20] [users] from the server
Totally fetched [20] [users] from the server
Attempt to fetch [50] [projects] from the server
Totally fetched [50] [projects] from the server
Projects number to fetch via API is 50
Repos number to fetch via API is 50
Successfully fetched pull requests in  [10.751255989074707]
Users count: 20
Projects count: 50
Repos count: 50
Pull requests count: 22
Finished preparing data

[2020-12-16 21:00:12,209 DEBUG Engine.shellexec.Task] Task was finished with exit code 0: python util/data_preparation/bitbucket_prepare_data.py
[2020-12-16 21:00:12,209 DEBUG Engine] Module config: local {'class': 'bzt.modules.provisioning.Local'}
[2020-12-16 21:00:12,209 DEBUG root] Importing module: bzt.modules.provisioning
[2020-12-16 21:00:12,209 DEBUG root] Loading class: 'Local' from <module 'bzt.modules.provisioning' from '/usr/local/lib/python3.8/dist-packages/bzt/modules/provisioning.py'>
[2020-12-16 21:00:12,209 DEBUG Engine] Module config: jmeter {'class': 'bzt.modules.jmeter.JMeterExecutor', 'protocol-handlers': {'http': 'bzt.jmx.http.HTTPProtocolHandler'}, 'plugins': ['jpgc-casutg', 'jpgc-dummy', 'jpgc-ffw', 'jpgc-fifo', 'jpgc-functions', 'jpgc-json', 'jpgc-perfmon', 'jpgc-prmctl', 'jpgc-tst', 'bzm-parallel=0.4', 'bzm-random-csv=0.6', 'jpgc-casutg=2.5', 'jpgc-dummy=0.2', 'jpgc-ffw=2.0', 'jpgc-fifo=0.2', 'jpgc-functions=2.1', 'jpgc-json=2.6', 'jpgc-perfmon=2.1', 'jpgc-prmctl=0.4', 'jpgc-tst=2.4', 'jpgc-wsc=0.3', 'tilln-sshmon=1.0', 'jpgc-synthesis=2.2'], 'properties': {'jmeter.save.saveservice.autoflush': 'true', 'jmeter.save.saveservice.connect_time': 'true', 'jmeterengine.force.system.exit': 'true', 'summariser.name': ''}, 'version': '5.2.1', 'detect-plugins': True, 'memory-xmx': '8G', 'system-properties': {'server.rmi.ssl.disable': True, 'java.rmi.server.hostname': 'localhost', 'httpsampler.ignore_failed_embedded_resources': 'true'}}
[2020-12-16 21:00:12,209 DEBUG root] Importing module: bzt.modules.jmeter
[2020-12-16 21:00:12,217 DEBUG root] Loading class: 'JMeterExecutor' from <module 'bzt.modules.jmeter' from '/usr/local/lib/python3.8/dist-packages/bzt/modules/jmeter.py'>
[2020-12-16 21:00:12,217 DEBUG Engine] Module config: selenium {'class': 'bzt.modules.selenium.SeleniumExecutor', 'chromedriver': {'version': '86.0.4240.22'}}
[2020-12-16 21:00:12,218 DEBUG root] Importing module: bzt.modules.selenium
[2020-12-16 21:00:12,218 DEBUG root] Loading class: 'SeleniumExecutor' from <module 'bzt.modules.selenium' from '/usr/local/lib/python3.8/dist-packages/bzt/modules/selenium.py'>
[2020-12-16 21:00:12,218 DEBUG Engine.local] Preparing executor: jmeter/140178104345216
[2020-12-16 21:00:12,218 DEBUG Engine] New artifact filename: /dc-app-performance-toolkit/app/results/bitbucket/2020-12-16_20-59-38/jmeter.log
[2020-12-16 21:00:12,218 DEBUG Engine.jmeter] Checking if port 4445 is free
[2020-12-16 21:00:12,218 DEBUG Engine.jmeter] Port 4445 is free
[2020-12-16 21:00:12,218 DEBUG Engine.jmeter] Using port 4445 for management
[2020-12-16 21:00:12,218 DEBUG Engine.jmeter] Setting JVM heap size to 8G
[2020-12-16 21:00:12,218 DEBUG Engine.jmeter] Additional system properties {'server.rmi.ssl.disable': True, 'java.rmi.server.hostname': 'localhost', 'httpsampler.ignore_failed_embedded_resources': 'true'}
[2020-12-16 21:00:12,218 DEBUG Engine] New artifact filename: /dc-app-performance-toolkit/app/results/bitbucket/2020-12-16_20-59-38/system.properties
[2020-12-16 21:00:12,218 DEBUG Engine.jmeter] Additional properties: {'jmeter.save.saveservice.autoflush': 'true', 'jmeter.save.saveservice.connect_time': 'true', 'jmeterengine.force.system.exit': 'true', 'summariser.name': '', 'admin_login': 'admin', 'admin_password': 'admin', 'application_hostname': 'bitbucket-loadbala-cs8s8ccqbfud-30797893.us-west-1.elb.amazonaws.com', 'application_protocol': 'http', 'application_port': '80', 'application_postfix': '', 'total_actions_per_hr': '32700', 'tmp_dir': '/tmp', 'ssh_key_url': 'https://centaurus-datasets.s3.us-east-2.amazonaws.com/bitbucket/ssh/id_rsa', 'jmeterengine.nongui.port': 4445, 'jmeterengine.nongui.maxport': 4445, 'jmeter.save.saveservice.timestamp_format': 'ms', 'sampleresult.default.encoding': 'UTF-8', 'user.classpath': '/dc-app-performance-toolkit/app/results/bitbucket/2020-12-16_20-59-38:/dc-app-performance-toolkit/app/jmeter'}
[2020-12-16 21:00:12,218 DEBUG Engine] New artifact filename: /dc-app-performance-toolkit/app/results/bitbucket/2020-12-16_20-59-38/jmeter-bzt.properties
[2020-12-16 21:00:12,219 DEBUG Engine.jmeter.JavaVM] Trying JavaVM: ['java', '-version']
[2020-12-16 21:00:12,219 DEBUG root] Executing shell: ['java', '-version'] at .
[2020-12-16 21:00:12,259 DEBUG Engine.jmeter.JavaVM] JavaVM output: openjdk version "1.8.0_265"
OpenJDK Runtime Environment (build 1.8.0_265-8u265-b01-0ubuntu2~18.04-b01)
OpenJDK 64-Bit Server VM (build 25.265-b01, mixed mode)

[2020-12-16 21:00:12,259 DEBUG Engine.jmeter.TclLibrary] We don't need to check tcl library on this platform
[2020-12-16 21:00:12,259 INFO Engine.jmeter.JMeter] Will install JMeter into /root/.bzt/jmeter-taurus/5.2.1
[2020-12-16 21:00:12,259 DEBUG Engine.jmeter.JMeter.JMeterMirrorsManager] Retrieving mirrors from page: https://jmeter.apache.org/download_jmeter.cgi
[2020-12-16 21:00:12,261 DEBUG urllib3.connectionpool] Starting new HTTPS connection (1): jmeter.apache.org:443
[2020-12-16 21:00:12,933 DEBUG urllib3.connectionpool] https://jmeter.apache.org:443 "GET /download_jmeter.cgi HTTP/1.1" 200 3330
[2020-12-16 21:00:12,934 DEBUG Engine.jmeter.JMeter.JMeterMirrorsManager] Parsing mirrors...
[2020-12-16 21:00:12,934 DEBUG Engine.jmeter.JMeter.JMeterMirrorsManager] Total mirrors: 12
[2020-12-16 21:00:12,934 INFO Engine.jmeter.JMeter] Downloading: https://apache.claz.org//jmeter/binaries/apache-jmeter-5.2.1.zip
[2020-12-16 21:00:12,935 DEBUG root] No progressbar for non-tty output: <_io.TextIOWrapper name='<stdout>' mode='w' encoding='utf-8'>
[2020-12-16 21:00:12,935 DEBUG urllib3.connectionpool] Starting new HTTPS connection (1): apache.claz.org:443
[2020-12-16 21:00:13,131 DEBUG urllib3.connectionpool] https://apache.claz.org:443 "GET //jmeter/binaries/apache-jmeter-5.2.1.zip HTTP/1.1" 200 65358454
[2020-12-16 21:01:04,071 DEBUG HTTPClient] File download resulted in exception: Traceback (most recent call last):
  File "/usr/local/lib/python3.8/dist-packages/bzt/utils.py", line 1202, in download_file
    self._save_file_from_connection(conn, filename, reporthook=reporthook)
  File "/usr/local/lib/python3.8/dist-packages/bzt/utils.py", line 1191, in _save_file_from_connection
    for chunk in conn.iter_content(chunk_size=block_size):
  File "/usr/local/lib/python3.8/dist-packages/requests/models.py", line 751, in generate
    for chunk in self.raw.stream(chunk_size, decode_content=True):
  File "/usr/local/lib/python3.8/dist-packages/urllib3/response.py", line 575, in stream
    data = self.read(amt=amt, decode_content=decode_content)
  File "/usr/local/lib/python3.8/dist-packages/urllib3/response.py", line 518, in read
    data = self._fp.read(amt) if not fp_closed else b""
  File "/usr/lib/python3.8/http/client.py", line 454, in read
    n = self.readinto(b)
  File "/usr/lib/python3.8/http/client.py", line 498, in readinto
    n = self.fp.readinto(b)
  File "/usr/lib/python3.8/socket.py", line 669, in readinto
    return self._sock.recv_into(b)
  File "/usr/lib/python3.8/ssl.py", line 1241, in recv_into
    return self.read(nbytes, buffer)
  File "/usr/lib/python3.8/ssl.py", line 1099, in read
    return self._sslobj.read(len, buffer)
KeyboardInterrupt

[2020-12-16 21:01:04,075 ERROR Engine.jmeter.JMeter] Error while downloading https://apache.claz.org//jmeter/binaries/apache-jmeter-5.2.1.zip: Unsuccessful download from https://apache.claz.org//jmeter/binaries/apache-jmeter-5.2.1.zip
[2020-12-16 21:01:04,075 INFO Engine.jmeter.JMeter] Downloading: https://apache.osuosl.org//jmeter/binaries/apache-jmeter-5.2.1.zip
[2020-12-16 21:01:04,075 DEBUG root] No progressbar for non-tty output: <_io.TextIOWrapper name='<stdout>' mode='w' encoding='utf-8'>
[2020-12-16 21:01:04,076 DEBUG urllib3.connectionpool] Starting new HTTPS connection (1): apache.osuosl.org:443
[2020-12-16 21:01:04,410 DEBUG urllib3.connectionpool] https://apache.osuosl.org:443 "GET //jmeter/binaries/apache-jmeter-5.2.1.zip HTTP/1.1" 200 65358454
[2020-12-16 21:01:05,970 DEBUG HTTPClient] File download resulted in exception: Traceback (most recent call last):
  File "/usr/local/lib/python3.8/dist-packages/bzt/utils.py", line 1202, in download_file
    self._save_file_from_connection(conn, filename, reporthook=reporthook)
  File "/usr/local/lib/python3.8/dist-packages/bzt/utils.py", line 1191, in _save_file_from_connection
    for chunk in conn.iter_content(chunk_size=block_size):
  File "/usr/local/lib/python3.8/dist-packages/requests/models.py", line 751, in generate
    for chunk in self.raw.stream(chunk_size, decode_content=True):
  File "/usr/local/lib/python3.8/dist-packages/urllib3/response.py", line 575, in stream
    data = self.read(amt=amt, decode_content=decode_content)
  File "/usr/local/lib/python3.8/dist-packages/urllib3/response.py", line 518, in read
    data = self._fp.read(amt) if not fp_closed else b""
  File "/usr/lib/python3.8/http/client.py", line 454, in read
    n = self.readinto(b)
  File "/usr/lib/python3.8/http/client.py", line 498, in readinto
    n = self.fp.readinto(b)
  File "/usr/lib/python3.8/socket.py", line 669, in readinto
    return self._sock.recv_into(b)
  File "/usr/lib/python3.8/ssl.py", line 1241, in recv_into
    return self.read(nbytes, buffer)
  File "/usr/lib/python3.8/ssl.py", line 1099, in read
    return self._sslobj.read(len, buffer)
KeyboardInterrupt

[2020-12-16 21:01:05,974 ERROR Engine.jmeter.JMeter] Error while downloading https://apache.osuosl.org//jmeter/binaries/apache-jmeter-5.2.1.zip: Unsuccessful download from https://apache.osuosl.org//jmeter/binaries/apache-jmeter-5.2.1.zip
[2020-12-16 21:01:05,974 INFO Engine.jmeter.JMeter] Downloading: https://ftp.wayne.edu/apache//jmeter/binaries/apache-jmeter-5.2.1.zip
[2020-12-16 21:01:05,975 DEBUG root] No progressbar for non-tty output: <_io.TextIOWrapper name='<stdout>' mode='w' encoding='utf-8'>
[2020-12-16 21:01:05,975 DEBUG urllib3.connectionpool] Starting new HTTPS connection (1): ftp.wayne.edu:443
[2020-12-16 21:01:06,348 DEBUG urllib3.connectionpool] https://ftp.wayne.edu:443 "GET /apache//jmeter/binaries/apache-jmeter-5.2.1.zip HTTP/1.1" 200 65358454
[2020-12-16 21:01:06,887 DEBUG HTTPClient] File download resulted in exception: Traceback (most recent call last):
  File "/usr/local/lib/python3.8/dist-packages/bzt/utils.py", line 1202, in download_file
    self._save_file_from_connection(conn, filename, reporthook=reporthook)
  File "/usr/local/lib/python3.8/dist-packages/bzt/utils.py", line 1191, in _save_file_from_connection
    for chunk in conn.iter_content(chunk_size=block_size):
  File "/usr/local/lib/python3.8/dist-packages/requests/models.py", line 751, in generate
    for chunk in self.raw.stream(chunk_size, decode_content=True):
  File "/usr/local/lib/python3.8/dist-packages/urllib3/response.py", line 575, in stream
    data = self.read(amt=amt, decode_content=decode_content)
  File "/usr/local/lib/python3.8/dist-packages/urllib3/response.py", line 518, in read
    data = self._fp.read(amt) if not fp_closed else b""
  File "/usr/lib/python3.8/http/client.py", line 454, in read
    n = self.readinto(b)
  File "/usr/lib/python3.8/http/client.py", line 498, in readinto
    n = self.fp.readinto(b)
  File "/usr/lib/python3.8/socket.py", line 669, in readinto
    return self._sock.recv_into(b)
  File "/usr/lib/python3.8/ssl.py", line 1241, in recv_into
    return self.read(nbytes, buffer)
  File "/usr/lib/python3.8/ssl.py", line 1099, in read
    return self._sslobj.read(len, buffer)
KeyboardInterrupt

[2020-12-16 21:01:06,889 ERROR Engine.jmeter.JMeter] Error while downloading https://ftp.wayne.edu/apache//jmeter/binaries/apache-jmeter-5.2.1.zip: Unsuccessful download from https://ftp.wayne.edu/apache//jmeter/binaries/apache-jmeter-5.2.1.zip
[2020-12-16 21:01:06,889 INFO Engine.jmeter.JMeter] Downloading: https://mirror.jframeworks.com/apache//jmeter/binaries/apache-jmeter-5.2.1.zip
[2020-12-16 21:01:06,889 DEBUG root] No progressbar for non-tty output: <_io.TextIOWrapper name='<stdout>' mode='w' encoding='utf-8'>
[2020-12-16 21:01:06,890 DEBUG urllib3.connectionpool] Starting new HTTPS connection (1): mirror.jframeworks.com:443
[2020-12-16 21:01:07,143 DEBUG urllib3.connectionpool] https://mirror.jframeworks.com:443 "GET /apache//jmeter/binaries/apache-jmeter-5.2.1.zip HTTP/1.1" 200 65358454
[2020-12-16 21:01:07,951 DEBUG HTTPClient] File download resulted in exception: Traceback (most recent call last):
  File "/usr/local/lib/python3.8/dist-packages/bzt/utils.py", line 1202, in download_file
    self._save_file_from_connection(conn, filename, reporthook=reporthook)
  File "/usr/local/lib/python3.8/dist-packages/bzt/utils.py", line 1191, in _save_file_from_connection
    for chunk in conn.iter_content(chunk_size=block_size):
  File "/usr/local/lib/python3.8/dist-packages/requests/models.py", line 751, in generate
    for chunk in self.raw.stream(chunk_size, decode_content=True):
  File "/usr/local/lib/python3.8/dist-packages/urllib3/response.py", line 575, in stream
    data = self.read(amt=amt, decode_content=decode_content)
  File "/usr/local/lib/python3.8/dist-packages/urllib3/response.py", line 518, in read
    data = self._fp.read(amt) if not fp_closed else b""
  File "/usr/lib/python3.8/http/client.py", line 454, in read
    n = self.readinto(b)
  File "/usr/lib/python3.8/http/client.py", line 498, in readinto
    n = self.fp.readinto(b)
  File "/usr/lib/python3.8/socket.py", line 669, in readinto
    return self._sock.recv_into(b)
  File "/usr/lib/python3.8/ssl.py", line 1241, in recv_into
    return self.read(nbytes, buffer)
  File "/usr/lib/python3.8/ssl.py", line 1099, in read
    return self._sslobj.read(len, buffer)
KeyboardInterrupt

[2020-12-16 21:01:07,953 ERROR Engine.jmeter.JMeter] Error while downloading https://mirror.jframeworks.com/apache//jmeter/binaries/apache-jmeter-5.2.1.zip: Unsuccessful download from https://mirror.jframeworks.com/apache//jmeter/binaries/apache-jmeter-5.2.1.zip
[2020-12-16 21:01:07,953 INFO Engine.jmeter.JMeter] Downloading: https://mirror.olnevhost.net/pub/apache//jmeter/binaries/apache-jmeter-5.2.1.zip
[2020-12-16 21:01:07,954 DEBUG root] No progressbar for non-tty output: <_io.TextIOWrapper name='<stdout>' mode='w' encoding='utf-8'>
[2020-12-16 21:01:07,955 DEBUG urllib3.connectionpool] Starting new HTTPS connection (1): mirror.olnevhost.net:443
[2020-12-16 21:01:08,569 DEBUG HTTPClient] File download resulted in exception: Traceback (most recent call last):
  File "/usr/local/lib/python3.8/dist-packages/bzt/utils.py", line 1201, in download_file
    with self.session.get(url, stream=True, data=data, timeout=timeout) as conn:
  File "/usr/local/lib/python3.8/dist-packages/requests/sessions.py", line 543, in get
    return self.request('GET', url, **kwargs)
  File "/usr/local/lib/python3.8/dist-packages/requests/sessions.py", line 530, in request
    resp = self.send(prep, **send_kwargs)
  File "/usr/local/lib/python3.8/dist-packages/requests/sessions.py", line 643, in send
    r = adapter.send(request, **kwargs)
  File "/usr/local/lib/python3.8/dist-packages/requests/adapters.py", line 439, in send
    resp = conn.urlopen(
  File "/usr/local/lib/python3.8/dist-packages/urllib3/connectionpool.py", line 670, in urlopen
    httplib_response = self._make_request(
  File "/usr/local/lib/python3.8/dist-packages/urllib3/connectionpool.py", line 381, in _make_request
    self._validate_conn(conn)
  File "/usr/local/lib/python3.8/dist-packages/urllib3/connectionpool.py", line 978, in _validate_conn
    conn.connect()
  File "/usr/local/lib/python3.8/dist-packages/urllib3/connection.py", line 362, in connect
    self.sock = ssl_wrap_socket(
  File "/usr/local/lib/python3.8/dist-packages/urllib3/util/ssl_.py", line 384, in ssl_wrap_socket
    return context.wrap_socket(sock, server_hostname=server_hostname)
  File "/usr/lib/python3.8/ssl.py", line 500, in wrap_socket
    return self.sslsocket_class._create(
  File "/usr/lib/python3.8/ssl.py", line 1040, in _create
    self.do_handshake()
  File "/usr/lib/python3.8/ssl.py", line 1309, in do_handshake
    self._sslobj.do_handshake()
KeyboardInterrupt

[2020-12-16 21:01:08,569 ERROR Engine.jmeter.JMeter] Error while downloading https://mirror.olnevhost.net/pub/apache//jmeter/binaries/apache-jmeter-5.2.1.zip: Unsuccessful download from https://mirror.olnevhost.net/pub/apache//jmeter/binaries/apache-jmeter-5.2.1.zip
[2020-12-16 21:01:08,570 INFO Engine.jmeter.JMeter] Downloading: https://mirrors.gigenet.com/apache//jmeter/binaries/apache-jmeter-5.2.1.zip
[2020-12-16 21:01:08,570 DEBUG root] No progressbar for non-tty output: <_io.TextIOWrapper name='<stdout>' mode='w' encoding='utf-8'>
[2020-12-16 21:01:08,571 DEBUG urllib3.connectionpool] Starting new HTTPS connection (1): mirrors.gigenet.com:443
[2020-12-16 21:01:08,837 DEBUG HTTPClient] File download resulted in exception: Traceback (most recent call last):
  File "/usr/local/lib/python3.8/dist-packages/bzt/utils.py", line 1201, in download_file
    with self.session.get(url, stream=True, data=data, timeout=timeout) as conn:
  File "/usr/local/lib/python3.8/dist-packages/requests/sessions.py", line 543, in get
    return self.request('GET', url, **kwargs)
  File "/usr/local/lib/python3.8/dist-packages/requests/sessions.py", line 530, in request
    resp = self.send(prep, **send_kwargs)
  File "/usr/local/lib/python3.8/dist-packages/requests/sessions.py", line 643, in send
    r = adapter.send(request, **kwargs)
  File "/usr/local/lib/python3.8/dist-packages/requests/adapters.py", line 439, in send
    resp = conn.urlopen(
  File "/usr/local/lib/python3.8/dist-packages/urllib3/connectionpool.py", line 670, in urlopen
    httplib_response = self._make_request(
  File "/usr/local/lib/python3.8/dist-packages/urllib3/connectionpool.py", line 426, in _make_request
    six.raise_from(e, None)
  File "<string>", line 3, in raise_from
  File "/usr/local/lib/python3.8/dist-packages/urllib3/connectionpool.py", line 421, in _make_request
    httplib_response = conn.getresponse()
  File "/usr/lib/python3.8/http/client.py", line 1322, in getresponse
    response.begin()
  File "/usr/lib/python3.8/http/client.py", line 303, in begin
    version, status, reason = self._read_status()
  File "/usr/lib/python3.8/http/client.py", line 264, in _read_status
    line = str(self.fp.readline(_MAXLINE + 1), "iso-8859-1")
  File "/usr/lib/python3.8/socket.py", line 669, in readinto
    return self._sock.recv_into(b)
  File "/usr/lib/python3.8/ssl.py", line 1241, in recv_into
    return self.read(nbytes, buffer)
  File "/usr/lib/python3.8/ssl.py", line 1099, in read
    return self._sslobj.read(len, buffer)
KeyboardInterrupt

[2020-12-16 21:01:08,837 ERROR Engine.jmeter.JMeter] Error while downloading https://mirrors.gigenet.com/apache//jmeter/binaries/apache-jmeter-5.2.1.zip: Unsuccessful download from https://mirrors.gigenet.com/apache//jmeter/binaries/apache-jmeter-5.2.1.zip
[2020-12-16 21:01:08,838 INFO Engine.jmeter.JMeter] Downloading: https://mirrors.ocf.berkeley.edu/apache//jmeter/binaries/apache-jmeter-5.2.1.zip
[2020-12-16 21:01:08,838 DEBUG root] No progressbar for non-tty output: <_io.TextIOWrapper name='<stdout>' mode='w' encoding='utf-8'>
[2020-12-16 21:01:08,839 DEBUG urllib3.connectionpool] Starting new HTTPS connection (1): mirrors.ocf.berkeley.edu:443
[2020-12-16 21:01:09,067 DEBUG HTTPClient] File download resulted in exception: Traceback (most recent call last):
  File "/usr/local/lib/python3.8/dist-packages/bzt/utils.py", line 1201, in download_file
    with self.session.get(url, stream=True, data=data, timeout=timeout) as conn:
  File "/usr/local/lib/python3.8/dist-packages/requests/sessions.py", line 543, in get
    return self.request('GET', url, **kwargs)
  File "/usr/local/lib/python3.8/dist-packages/requests/sessions.py", line 530, in request
    resp = self.send(prep, **send_kwargs)
  File "/usr/local/lib/python3.8/dist-packages/requests/sessions.py", line 643, in send
    r = adapter.send(request, **kwargs)
  File "/usr/local/lib/python3.8/dist-packages/requests/adapters.py", line 439, in send
    resp = conn.urlopen(
  File "/usr/local/lib/python3.8/dist-packages/urllib3/connectionpool.py", line 670, in urlopen
    httplib_response = self._make_request(
  File "/usr/local/lib/python3.8/dist-packages/urllib3/connectionpool.py", line 426, in _make_request
    six.raise_from(e, None)
  File "<string>", line 3, in raise_from
  File "/usr/local/lib/python3.8/dist-packages/urllib3/connectionpool.py", line 421, in _make_request
    httplib_response = conn.getresponse()
  File "/usr/lib/python3.8/http/client.py", line 1322, in getresponse
    response.begin()
  File "/usr/lib/python3.8/http/client.py", line 303, in begin
    version, status, reason = self._read_status()
  File "/usr/lib/python3.8/http/client.py", line 264, in _read_status
    line = str(self.fp.readline(_MAXLINE + 1), "iso-8859-1")
  File "/usr/lib/python3.8/socket.py", line 669, in readinto
    return self._sock.recv_into(b)
  File "/usr/lib/python3.8/ssl.py", line 1241, in recv_into
    return self.read(nbytes, buffer)
  File "/usr/lib/python3.8/ssl.py", line 1099, in read
    return self._sslobj.read(len, buffer)
KeyboardInterrupt

[2020-12-16 21:01:09,068 ERROR Engine.jmeter.JMeter] Error while downloading https://mirrors.ocf.berkeley.edu/apache//jmeter/binaries/apache-jmeter-5.2.1.zip: Unsuccessful download from https://mirrors.ocf.berkeley.edu/apache//jmeter/binaries/apache-jmeter-5.2.1.zip
[2020-12-16 21:01:09,068 INFO Engine.jmeter.JMeter] Downloading: https://mirrors.sonic.net/apache//jmeter/binaries/apache-jmeter-5.2.1.zip
[2020-12-16 21:01:09,069 DEBUG root] No progressbar for non-tty output: <_io.TextIOWrapper name='<stdout>' mode='w' encoding='utf-8'>
[2020-12-16 21:01:09,070 DEBUG urllib3.connectionpool] Starting new HTTPS connection (1): mirrors.sonic.net:443
[2020-12-16 21:01:09,283 DEBUG HTTPClient] File download resulted in exception: Traceback (most recent call last):
  File "/usr/local/lib/python3.8/dist-packages/bzt/utils.py", line 1201, in download_file
    with self.session.get(url, stream=True, data=data, timeout=timeout) as conn:
  File "/usr/local/lib/python3.8/dist-packages/requests/sessions.py", line 543, in get
    return self.request('GET', url, **kwargs)
  File "/usr/local/lib/python3.8/dist-packages/requests/sessions.py", line 530, in request
    resp = self.send(prep, **send_kwargs)
  File "/usr/local/lib/python3.8/dist-packages/requests/sessions.py", line 643, in send
    r = adapter.send(request, **kwargs)
  File "/usr/local/lib/python3.8/dist-packages/requests/adapters.py", line 439, in send
    resp = conn.urlopen(
  File "/usr/local/lib/python3.8/dist-packages/urllib3/connectionpool.py", line 670, in urlopen
    httplib_response = self._make_request(
  File "/usr/local/lib/python3.8/dist-packages/urllib3/connectionpool.py", line 381, in _make_request
    self._validate_conn(conn)
  File "/usr/local/lib/python3.8/dist-packages/urllib3/connectionpool.py", line 978, in _validate_conn
    conn.connect()
  File "/usr/local/lib/python3.8/dist-packages/urllib3/connection.py", line 362, in connect
    self.sock = ssl_wrap_socket(
  File "/usr/local/lib/python3.8/dist-packages/urllib3/util/ssl_.py", line 384, in ssl_wrap_socket
    return context.wrap_socket(sock, server_hostname=server_hostname)
  File "/usr/lib/python3.8/ssl.py", line 500, in wrap_socket
    return self.sslsocket_class._create(
  File "/usr/lib/python3.8/ssl.py", line 1040, in _create
    self.do_handshake()
  File "/usr/lib/python3.8/ssl.py", line 1309, in do_handshake
    self._sslobj.do_handshake()
KeyboardInterrupt

[2020-12-16 21:01:09,283 ERROR Engine.jmeter.JMeter] Error while downloading https://mirrors.sonic.net/apache//jmeter/binaries/apache-jmeter-5.2.1.zip: Unsuccessful download from https://mirrors.sonic.net/apache//jmeter/binaries/apache-jmeter-5.2.1.zip
[2020-12-16 21:01:09,284 INFO Engine.jmeter.JMeter] Downloading: https://downloads.apache.org//jmeter/binaries/apache-jmeter-5.2.1.zip
[2020-12-16 21:01:09,284 DEBUG root] No progressbar for non-tty output: <_io.TextIOWrapper name='<stdout>' mode='w' encoding='utf-8'>
[2020-12-16 21:01:09,286 DEBUG urllib3.connectionpool] Starting new HTTPS connection (1): downloads.apache.org:443
[2020-12-16 21:01:09,519 DEBUG HTTPClient] File download resulted in exception: Traceback (most recent call last):
  File "/usr/local/lib/python3.8/dist-packages/bzt/utils.py", line 1201, in download_file
    with self.session.get(url, stream=True, data=data, timeout=timeout) as conn:
  File "/usr/local/lib/python3.8/dist-packages/requests/sessions.py", line 543, in get
    return self.request('GET', url, **kwargs)
  File "/usr/local/lib/python3.8/dist-packages/requests/sessions.py", line 530, in request
    resp = self.send(prep, **send_kwargs)
  File "/usr/local/lib/python3.8/dist-packages/requests/sessions.py", line 643, in send
    r = adapter.send(request, **kwargs)
  File "/usr/local/lib/python3.8/dist-packages/requests/adapters.py", line 439, in send
    resp = conn.urlopen(
  File "/usr/local/lib/python3.8/dist-packages/urllib3/connectionpool.py", line 670, in urlopen
    httplib_response = self._make_request(
  File "/usr/local/lib/python3.8/dist-packages/urllib3/connectionpool.py", line 381, in _make_request
    self._validate_conn(conn)
  File "/usr/local/lib/python3.8/dist-packages/urllib3/connectionpool.py", line 978, in _validate_conn
    conn.connect()
  File "/usr/local/lib/python3.8/dist-packages/urllib3/connection.py", line 362, in connect
    self.sock = ssl_wrap_socket(
  File "/usr/local/lib/python3.8/dist-packages/urllib3/util/ssl_.py", line 384, in ssl_wrap_socket
    return context.wrap_socket(sock, server_hostname=server_hostname)
  File "/usr/lib/python3.8/ssl.py", line 500, in wrap_socket
    return self.sslsocket_class._create(
  File "/usr/lib/python3.8/ssl.py", line 1040, in _create
    self.do_handshake()
  File "/usr/lib/python3.8/ssl.py", line 1309, in do_handshake
    self._sslobj.do_handshake()
KeyboardInterrupt

[2020-12-16 21:01:09,520 ERROR Engine.jmeter.JMeter] Error while downloading https://downloads.apache.org//jmeter/binaries/apache-jmeter-5.2.1.zip: Unsuccessful download from https://downloads.apache.org//jmeter/binaries/apache-jmeter-5.2.1.zip
[2020-12-16 21:01:09,521 INFO Engine.jmeter.JMeter] Downloading: https://archive.apache.org/dist/jmeter/binaries/apache-jmeter-5.2.1.zip
[2020-12-16 21:01:09,521 DEBUG root] No progressbar for non-tty output: <_io.TextIOWrapper name='<stdout>' mode='w' encoding='utf-8'>
[2020-12-16 21:01:09,523 DEBUG urllib3.connectionpool] Starting new HTTPS connection (1): archive.apache.org:443
[2020-12-16 21:01:09,757 DEBUG HTTPClient] File download resulted in exception: Traceback (most recent call last):
  File "/usr/local/lib/python3.8/dist-packages/bzt/utils.py", line 1201, in download_file
    with self.session.get(url, stream=True, data=data, timeout=timeout) as conn:
  File "/usr/local/lib/python3.8/dist-packages/requests/sessions.py", line 543, in get
    return self.request('GET', url, **kwargs)
  File "/usr/local/lib/python3.8/dist-packages/requests/sessions.py", line 530, in request
    resp = self.send(prep, **send_kwargs)
  File "/usr/local/lib/python3.8/dist-packages/requests/sessions.py", line 643, in send
    r = adapter.send(request, **kwargs)
  File "/usr/local/lib/python3.8/dist-packages/requests/adapters.py", line 439, in send
    resp = conn.urlopen(
  File "/usr/local/lib/python3.8/dist-packages/urllib3/connectionpool.py", line 670, in urlopen
    httplib_response = self._make_request(
  File "/usr/local/lib/python3.8/dist-packages/urllib3/connectionpool.py", line 381, in _make_request
    self._validate_conn(conn)
  File "/usr/local/lib/python3.8/dist-packages/urllib3/connectionpool.py", line 978, in _validate_conn
    conn.connect()
  File "/usr/local/lib/python3.8/dist-packages/urllib3/connection.py", line 362, in connect
    self.sock = ssl_wrap_socket(
  File "/usr/local/lib/python3.8/dist-packages/urllib3/util/ssl_.py", line 384, in ssl_wrap_socket
    return context.wrap_socket(sock, server_hostname=server_hostname)
  File "/usr/lib/python3.8/ssl.py", line 500, in wrap_socket
    return self.sslsocket_class._create(
  File "/usr/lib/python3.8/ssl.py", line 1040, in _create
    self.do_handshake()
  File "/usr/lib/python3.8/ssl.py", line 1309, in do_handshake
    self._sslobj.do_handshake()
KeyboardInterrupt

[2020-12-16 21:01:09,757 ERROR Engine.jmeter.JMeter] Error while downloading https://archive.apache.org/dist/jmeter/binaries/apache-jmeter-5.2.1.zip: Unsuccessful download from https://archive.apache.org/dist/jmeter/binaries/apache-jmeter-5.2.1.zip
[2020-12-16 21:01:09,758 INFO Engine.jmeter.JMeter] Downloading: ftp://apache.cs.utah.edu/apache.org//jmeter/binaries/apache-jmeter-5.2.1.zip
[2020-12-16 21:01:09,758 DEBUG root] No progressbar for non-tty output: <_io.TextIOWrapper name='<stdout>' mode='w' encoding='utf-8'>
[2020-12-16 21:01:09,759 DEBUG HTTPClient] File download resulted in exception: Traceback (most recent call last):
  File "/usr/local/lib/python3.8/dist-packages/bzt/utils.py", line 1201, in download_file
    with self.session.get(url, stream=True, data=data, timeout=timeout) as conn:
  File "/usr/local/lib/python3.8/dist-packages/requests/sessions.py", line 543, in get
    return self.request('GET', url, **kwargs)
  File "/usr/local/lib/python3.8/dist-packages/requests/sessions.py", line 530, in request
    resp = self.send(prep, **send_kwargs)
  File "/usr/local/lib/python3.8/dist-packages/requests/sessions.py", line 637, in send
    adapter = self.get_adapter(url=request.url)
  File "/usr/local/lib/python3.8/dist-packages/requests/sessions.py", line 730, in get_adapter
    raise InvalidSchema("No connection adapters were found for {!r}".format(url))
requests.exceptions.InvalidSchema: No connection adapters were found for 'ftp://apache.cs.utah.edu/apache.org//jmeter/binaries/apache-jmeter-5.2.1.zip'

[2020-12-16 21:01:09,759 ERROR Engine.jmeter.JMeter] Error while downloading ftp://apache.cs.utah.edu/apache.org//jmeter/binaries/apache-jmeter-5.2.1.zip: Unsuccessful download from ftp://apache.cs.utah.edu/apache.org//jmeter/binaries/apache-jmeter-5.2.1.zip
[2020-12-16 21:01:09,759 INFO Engine.jmeter.JMeter] Downloading: ftp://ftp.osuosl.org/pub/apache//jmeter/binaries/apache-jmeter-5.2.1.zip
[2020-12-16 21:01:09,759 DEBUG root] No progressbar for non-tty output: <_io.TextIOWrapper name='<stdout>' mode='w' encoding='utf-8'>
[2020-12-16 21:01:09,760 DEBUG HTTPClient] File download resulted in exception: Traceback (most recent call last):
  File "/usr/local/lib/python3.8/dist-packages/bzt/utils.py", line 1201, in download_file
    with self.session.get(url, stream=True, data=data, timeout=timeout) as conn:
  File "/usr/local/lib/python3.8/dist-packages/requests/sessions.py", line 543, in get
    return self.request('GET', url, **kwargs)
  File "/usr/local/lib/python3.8/dist-packages/requests/sessions.py", line 530, in request
    resp = self.send(prep, **send_kwargs)
  File "/usr/local/lib/python3.8/dist-packages/requests/sessions.py", line 637, in send
    adapter = self.get_adapter(url=request.url)
  File "/usr/local/lib/python3.8/dist-packages/requests/sessions.py", line 730, in get_adapter
    raise InvalidSchema("No connection adapters were found for {!r}".format(url))
requests.exceptions.InvalidSchema: No connection adapters were found for 'ftp://ftp.osuosl.org/pub/apache//jmeter/binaries/apache-jmeter-5.2.1.zip'

[2020-12-16 21:01:09,760 ERROR Engine.jmeter.JMeter] Error while downloading ftp://ftp.osuosl.org/pub/apache//jmeter/binaries/apache-jmeter-5.2.1.zip: Unsuccessful download from ftp://ftp.osuosl.org/pub/apache//jmeter/binaries/apache-jmeter-5.2.1.zip
[2020-12-16 21:01:09,760 ERROR root] Internal Error: JMeter download failed: No more links to try
[2020-12-16 21:01:09,761 DEBUG root] TaurusInternalException: JMeter download failed: No more links to try
  File "/usr/local/lib/python3.8/dist-packages/bzt/cli.py", line 259, in perform
    self.engine.prepare()
  File "/usr/local/lib/python3.8/dist-packages/bzt/engine/engine.py", line 216, in prepare
    self.__prepare_provisioning()
  File "/usr/local/lib/python3.8/dist-packages/bzt/engine/engine.py", line 619, in __prepare_provisioning
    self.provisioning.prepare()
  File "/usr/local/lib/python3.8/dist-packages/bzt/modules/provisioning.py", line 72, in prepare
    executor.prepare()
  File "/usr/local/lib/python3.8/dist-packages/bzt/modules/jmeter.py", line 234, in prepare
    self.install_required_tools()
  File "/usr/local/lib/python3.8/dist-packages/bzt/modules/jmeter.py", line 787, in install_required_tools
    tool.install()
  File "/usr/local/lib/python3.8/dist-packages/bzt/modules/jmeter.py", line 1532, in install
    self.__install_jmeter(dest)
  File "/usr/local/lib/python3.8/dist-packages/bzt/modules/jmeter.py", line 1460, in __install_jmeter
    jmeter_dist = self._download()
  File "/usr/local/lib/python3.8/dist-packages/bzt/utils.py", line 1336, in _download
    raise TaurusInternalException("%s download failed: No more links to try" % self.tool_name)
[2020-12-16 21:01:09,761 INFO Engine] Post-processing...
[2020-12-16 21:01:09,761 DEBUG Engine.local] Post-process jmeter/jmeter
[2020-12-16 21:01:09,761 DEBUG Engine] Add existing artifact (move=True): None
[2020-12-16 21:01:09,761 DEBUG Engine.local] Exception in post_process of JMeterExecutor: expected str, bytes or os.PathLike object, not NoneType Traceback (most recent call last):
  File "/usr/local/lib/python3.8/dist-packages/bzt/modules/provisioning.py", line 159, in post_process
    executor.post_process()
  File "/usr/local/lib/python3.8/dist-packages/bzt/modules/jmeter.py", line 389, in post_process
    self.engine.existing_artifact(self.modified_jmx, True)
  File "/usr/local/lib/python3.8/dist-packages/bzt/engine/engine.py", line 388, in existing_artifact
    new_filename = os.path.basename(filename) if target_filename is None else target_filename
  File "/usr/lib/python3.8/posixpath.py", line 142, in basename
    p = os.fspath(p)
TypeError: expected str, bytes or os.PathLike object, not NoneType

[2020-12-16 21:01:09,761 DEBUG Engine.local] Post-process selenium/140178102654432
[2020-12-16 21:01:09,761 DEBUG Engine.local] Exception in post_process of SeleniumExecutor: 'NoneType' object has no attribute 'post_process' Traceback (most recent call last):
  File "/usr/local/lib/python3.8/dist-packages/bzt/modules/provisioning.py", line 159, in post_process
    executor.post_process()
  File "/usr/local/lib/python3.8/dist-packages/bzt/modules/selenium.py", line 219, in post_process
    self.runner.post_process()
AttributeError: 'NoneType' object has no attribute 'post_process'

[2020-12-16 21:01:09,762 DEBUG Engine] post_process: expected str, bytes or os.PathLike object, not NoneType
Traceback (most recent call last):
  File "/usr/local/lib/python3.8/dist-packages/bzt/engine/engine.py", line 340, in post_process
    module.post_process()
  File "/usr/local/lib/python3.8/dist-packages/bzt/modules/provisioning.py", line 176, in post_process
    reraise(exc_info, exc_value)
  File "/usr/local/lib/python3.8/dist-packages/bzt/utils.py", line 102, in reraise
    raise exc
  File "/usr/local/lib/python3.8/dist-packages/bzt/modules/provisioning.py", line 159, in post_process
    executor.post_process()
  File "/usr/local/lib/python3.8/dist-packages/bzt/modules/jmeter.py", line 389, in post_process
    self.engine.existing_artifact(self.modified_jmx, True)
  File "/usr/local/lib/python3.8/dist-packages/bzt/engine/engine.py", line 388, in existing_artifact
    new_filename = os.path.basename(filename) if target_filename is None else target_filename
  File "/usr/lib/python3.8/posixpath.py", line 142, in basename
    p = os.fspath(p)
TypeError: expected str, bytes or os.PathLike object, not NoneType

[2020-12-16 21:01:09,762 DEBUG Engine.consolidator] Consolidator buffer[0]: dict_keys([])
[2020-12-16 21:01:09,762 INFO Engine.shellexec.Task] Starting shell command: python util/analytics/analytics.py bitbucket
[2020-12-16 21:01:09,762 DEBUG root] Executing shell: python util/analytics/analytics.py bitbucket at /dc-app-performance-toolkit/app
[2020-12-16 21:01:09,949 WARNING Engine.shellexec.Task] Errors for python util/analytics/analytics.py bitbucket:
Traceback (most recent call last):
  File "util/analytics/analytics.py", line 144, in <module>
    main()
  File "util/analytics/analytics.py", line 137, in main
    collector = AnalyticsCollector(application)
  File "util/analytics/analytics.py", line 33, in __init__
    self.results_log = ResultsFileReader()
  File "/dc-app-performance-toolkit/app/util/analytics/log_reader.py", line 120, in __init__
    self.results_log = self.get_results_log()
  File "/dc-app-performance-toolkit/app/util/analytics/log_reader.py", line 124, in get_results_log
    self.validate_file_exists(results_log_path)
  File "/dc-app-performance-toolkit/app/util/analytics/log_reader.py", line 16, in validate_file_exists
    raise Exception(f'{path} does not exist')
Exception: /dc-app-performance-toolkit/app/results/bitbucket/2020-12-16_20-59-38/results.csv does not exist

[2020-12-16 21:01:09,949 DEBUG Engine.shellexec.Task] Task was finished with exit code 1: python util/analytics/analytics.py bitbucket
[2020-12-16 21:01:09,950 DEBUG Engine] post_process: Command 'python util/analytics/analytics.py bitbucket' returned non-zero exit status 1.
Traceback (most recent call last):
  File "/usr/local/lib/python3.8/dist-packages/bzt/engine/engine.py", line 340, in post_process
    module.post_process()
  File "/usr/local/lib/python3.8/dist-packages/bzt/modules/shellexec.py", line 159, in post_process
    task.start()
  File "/usr/local/lib/python3.8/dist-packages/bzt/modules/shellexec.py", line 217, in start
    self._get_results()
  File "/usr/local/lib/python3.8/dist-packages/bzt/modules/shellexec.py", line 244, in _get_results
    raise CalledProcessError(self.process.returncode, self)
subprocess.CalledProcessError: Command 'python util/analytics/analytics.py bitbucket' returned non-zero exit status 1.

[2020-12-16 21:01:09,951 DEBUG Engine.Configuration] Dumping YAML config into /dc-app-performance-toolkit/app/results/bitbucket/2020-12-16_20-59-38/effective.yml
[2020-12-16 21:01:09,964 DEBUG Engine.Configuration] Dumping JSON config into /dc-app-performance-toolkit/app/results/bitbucket/2020-12-16_20-59-38/effective.json
[2020-12-16 21:01:09,965 DEBUG root] TypeError: expected str, bytes or os.PathLike object, not NoneType
  File "/usr/local/lib/python3.8/dist-packages/bzt/cli.py", line 267, in perform
    self.engine.post_process()
  File "/usr/local/lib/python3.8/dist-packages/bzt/engine/engine.py", line 354, in post_process
    reraise(exc_info, exc_value)
  File "/usr/local/lib/python3.8/dist-packages/bzt/utils.py", line 102, in reraise
    raise exc
  File "/usr/local/lib/python3.8/dist-packages/bzt/engine/engine.py", line 340, in post_process
    module.post_process()
  File "/usr/local/lib/python3.8/dist-packages/bzt/modules/provisioning.py", line 176, in post_process
    reraise(exc_info, exc_value)
  File "/usr/local/lib/python3.8/dist-packages/bzt/utils.py", line 102, in reraise
    raise exc
  File "/usr/local/lib/python3.8/dist-packages/bzt/modules/provisioning.py", line 159, in post_process
    executor.post_process()
  File "/usr/local/lib/python3.8/dist-packages/bzt/modules/jmeter.py", line 389, in post_process
    self.engine.existing_artifact(self.modified_jmx, True)
  File "/usr/local/lib/python3.8/dist-packages/bzt/engine/engine.py", line 388, in existing_artifact
    new_filename = os.path.basename(filename) if target_filename is None else target_filename
  File "/usr/lib/python3.8/posixpath.py", line 142, in basename
    p = os.fspath(p)
[2020-12-16 21:01:09,965 INFO root] Artifacts dir: /dc-app-performance-toolkit/app/results/bitbucket/2020-12-16_20-59-38
[2020-12-16 21:01:09,965 WARNING root] Done performing with code: 1
[2020-12-16 21:01:09,965 DEBUG root] Closing log handler: /dc-app-performance-toolkit/app/results/bitbucket/2020-12-16_20-59-38/bzt.log
